{"version": 2, "width": 80, "height": 24, "timestamp": 1750023750, "env": {"SHELL": "/bin/bash", "TERM": "xterm-256color"}}
[0.166674, "o", "\u001b[?2004h"]
[0.18031, "o", "\u001b]0;alena@alena-VirtualBox: ~/fast_api2\u0007\u001b[01;32malena@alena-VirtualBox\u001b[00m:\u001b[01;34m~/fast_api2\u001b[00m$ "]
[8.134514, "o", "\u001b[7mcat Dockerfile\u001b[27m"]
[8.647914, "o", "\b\b\b\b\b\b\b\b\b\b\b\b\b\bcat Dockerfile\r\n\u001b[?2004l\r"]
[8.666209, "o", "FROM python:3.11-slim\r"]
[8.666411, "o", "\r\n"]
[8.666515, "o", "\r"]
[8.666616, "o", "\r\n"]
[8.667169, "o", "WORKDIR /app\r\r\n\r\r\nCOPY . /app\r\r\n\r\r\nRUN pip install --no-cache-dir -r requirements.txt\r\r\n\r\r\nCMD [\"uvicorn\", \"main:app\", \"--host\", \"0.0.0.0\", \"--port\", \"8000\"]"]
[8.681703, "o", "\u001b[?2004h\u001b]0;alena@alena-VirtualBox: ~/fast_api2\u0007\u001b[01;32malena@alena-VirtualBox\u001b[00m:\u001b[01;34m~/fast_api2\u001b[00m$ "]
[13.980544, "o", "\u001b[7mcat docker-compose.yml\u001b[27m"]
[14.456458, "o", "\b\b\b\b\b\b\b\b\b\b\b\b\b\b\b\b\b\b\b\b\b\bcat docker-compose.yml"]
[14.457283, "o", "\r\n"]
[14.458026, "o", "\u001b[?2004l\r"]
[14.471935, "o", "version: \"3.8\"\r\r\n\r\r\nservices:\r\r\n  web:\r\r\n    build: .\r\r\n    container_name: fastapi_app\r\r\n    ports:\r\r\n      - \"8000:8000\"\r\r\n    depends_on:\r\r\n      - db\r\r\n    env_file:\r\r\n      - .env\r\r\n    restart: always\r\r\n\r\r\n  db:\r\r\n    image: mysql:8\r\r\n    container_name: mysql_db\r\r\n    environment:\r\r\n      MYSQL_ROOT_PASSWORD: root\r\r\n      MYSQL_DATABASE: tasks\r\r\n      MYSQL_USER: user\r\r\n      MYSQL_PASSWORD: password\r\r\n    volumes:\r\r\n      - db_data:/var/lib/mysql\r\r\n    ports:\r\r\n      - \"3306:3306\"\r\r\n    restart: always\r\r\n\r\r\nvolumes:\r\r\n  db_data:\r\r\n"]
[14.472655, "o", "\u001b[?2004h"]
[14.472969, "o", "\u001b]0;alena@alena-VirtualBox: ~/fast_api2\u0007\u001b[01;32malena@alena-VirtualBox\u001b[00m:\u001b[01;34m~/fast_api2\u001b[00m$ "]
[19.593315, "o", "\u001b[7mcat .env\u001b[27m"]
[20.27195, "o", "\b\b\b\b\b\b\b\bcat .env\r\n\u001b[?2004l\r"]
[20.305376, "o", "MYSQL_ROOT_PASSWORD=root\r\nMYSQL_USER=user\r\nMYSQL_PASSWORD=password\r\nMYSQL_DATABASE=tasks\r\n\u001b[?2004h"]
[20.318501, "o", "\u001b]0;alena@alena-VirtualBox: ~/fast_api2\u0007\u001b[01;32malena@alena-VirtualBox\u001b[00m:\u001b[01;34m~/fast_api2\u001b[00m$ "]
[27.293364, "o", "\u001b[7mcat requirements.txt\u001b[27m"]
[27.904586, "o", "\b\b\b\b\b\b\b\b\b\b\b\b\b\b\b\b\b\b\b\bcat requirements.txt\r\n\u001b[?2004l\r"]
[27.928207, "o", "fastapi\r\nuvicorn\r\nsqlalchemy  \r\npasslib\r\n"]
[27.928886, "o", "python-jose\r\npython-multipart\r\npydantic\r\npymysql\r\ncryptography\r\n"]
[27.934711, "o", "\u001b[?2004h\u001b]0;alena@alena-VirtualBox: ~/fast_api2\u0007\u001b[01;32malena@alena-VirtualBox\u001b[00m:\u001b[01;34m~/fast_api2\u001b[00m$ "]
[33.481469, "o", "\u001b[7mdocker-compose build\u001b[27m"]
[33.957235, "o", "\b\b\b\b\b\b\b\b\b\b\b\b\b\b\b\b\b\b\b\bdocker-compose build\r\n\u001b[?2004l\r"]
[35.747988, "o", "db uses an image, skipping\r\n"]
[35.74929, "o", "Building web\r\n"]
[36.292083, "o", "DEPRECATED: The legacy builder is deprecated and will be removed in a future release."]
[36.292284, "o", "\r\n            Install the buildx component to build images with BuildKit:\r\n"]
[36.293013, "o", "            https://docs.docker.com/go/buildx/\r\n\r\n"]
[36.523918, "o", "Sending build context to Docker daemon  164.4kB\r\r\r\n"]
[36.548794, "o", "Step 1/5 : FROM python:3.11-slim\r\n ---> be3324b8ee1a\r\nStep 2/5 : WORKDIR /app\r\n"]
[36.555228, "o", " ---> Using cache\r\n ---> e7c3a62fe187\r\nStep 3/5 : COPY . /app\r\n"]
[36.56458, "o", " ---> Using cache\r\n"]
[36.56531, "o", " ---> d8178d9b0099\r\n"]
[36.568038, "o", "Step 4/5 : RUN pip install --no-cache-dir -r requirements.txt"]
[36.57153, "o", "\r\n"]
[36.574683, "o", " ---> Using cache"]
[36.584933, "o", "\r\n ---> 410e1bec2b0d\r\nStep 5/5 : CMD [\"uvicorn\", \"main:app\", \"--host\", \"0.0.0.0\", \"--port\", \"8000\"]\r\n ---> Using cache\r\n ---> 1f7d803b601d\r\nSuccessfully built 1f7d803b601d\r\n"]
[36.594962, "o", "Successfully tagged fast_api2_web:latest"]
[36.59547, "o", "\r\n"]
[36.873037, "o", "\u001b[?2004h\u001b]0;alena@alena-VirtualBox: ~/fast_api2\u0007\u001b[01;32malena@alena-VirtualBox\u001b[00m:\u001b[01;34m~/fast_api2\u001b[00m$ "]
[42.121947, "o", "\u001b[7mdocker-compose up\u001b[27m"]
[42.717463, "o", "\b\b\b\b\b\b\b\b\b\b\b\b\b\b\b\b\bdocker-compose up\r\n\u001b[?2004l\r"]
[43.467115, "o", "\u001b[33mWARNING\u001b[0m: The Docker Engine you're using is running in swarm mode."]
[43.468242, "o", "\r\n"]
[43.47048, "o", "\r\nCompose does not use swarm mode to deploy services to multiple nodes in a swarm. All containers will be scheduled on the current node.\r\n\r\nTo deploy your application across the swarm, use `docker stack deploy`.\r\n\r\n"]
[43.851398, "o", "Starting mysql_db ... \r\r\n"]
[45.177318, "o", "\u001b[1A\u001b[2K\rStarting mysql_db ... \u001b[32mdone\u001b[0m\r\u001b[1B"]
[45.190983, "o", "Starting fastapi_app ... \r\r\n"]
[47.161821, "o", "\u001b[1A\u001b[2K\r"]
[47.16205, "o", "Starting fastapi_app ... \u001b[32mdone\u001b[0m\r"]
[47.163175, "o", "\u001b[1B"]
[47.164321, "o", "Attaching to mysql_db, fastapi_app\r\n"]
[47.196877, "o", "\u001b[33mmysql_db |\u001b[0m 2025-06-15 21:43:16+00:00 [Note] [Entrypoint]: Entrypoint script for MySQL Server 8.4.5-1.el9 started.\r\n\u001b[33mmysql_db |\u001b[0m 2025-06-15 21:43:17+00:00 [Note] [Entrypoint]: Switching to dedicated user 'mysql'\r\n\u001b[33mmysql_db |\u001b[0m 2025-06-15 21:43:17+00:00 [Note] [Entrypoint]: Entrypoint script for MySQL Server 8.4.5-1.el9 started.\r\n"]
[47.69568, "o", "\u001b[33mmysql_db |\u001b[0m '/var/lib/mysql/mysql.sock' -> '/var/run/mysqld/mysqld.sock'\r\n"]
[48.169468, "o", "\u001b[33mmysql_db |\u001b[0m 2025-06-15T21:43:18.879576Z 0 [System] [MY-015015] [Server] MySQL Server - start.\r\n"]
[48.175996, "o", "\u001b[33mmysql_db |\u001b[0m 2025-06-15T21:43:19.211339Z 0 [System] [MY-010116] [Server] /usr/sbin/mysqld (mysqld 8.4.5) starting as process 1\r\n"]
[48.231081, "o", "\u001b[33mmysql_db |\u001b[0m 2025-06-15T21:43:19.253653Z 1 [System] [MY-013576] [InnoDB] InnoDB initialization has started.\r\n"]
[49.108021, "o", "\u001b[36mfastapi_app |\u001b[0m INFO:     Started server process [1]\r\n"]
[50.920891, "o", "\u001b[36mfastapi_app |\u001b[0m INFO:     Waiting for application startup."]
[50.957219, "o", "\r\n"]
[51.432368, "o", "\u001b[36mfastapi_app |\u001b[0m ERROR:    Traceback (most recent call last):\r\n\u001b[36mfastapi_app |\u001b[0m   File \"/usr/local/lib/python3.11/site-packages/pymysql/connections.py\", line 649, in connect\r\n\u001b[36mfastapi_app |\u001b[0m     sock = socket.create_connection(\r\n\u001b[36mfastapi_app |\u001b[0m            ^^^^^^^^^^^^^^^^^^^^^^^^^\r\n\u001b[36mfastapi_app |\u001b[0m   File \"/usr/local/lib/python3.11/socket.py\", line 863, in create_connection\r\n\u001b[36mfastapi_app |\u001b[0m     raise exceptions[0]\r\n\u001b[36mfastapi_app |\u001b[0m   File \"/usr/local/lib/python3.11/socket.py\", line 848, in create_connection"]
[51.436105, "o", "\r\n\u001b[36mfastapi_app |\u001b[0m     sock.connect(sa)\r\n\u001b[36mfastapi_app |\u001b[0m ConnectionRefusedError: [Errno 111] Connection refused"]
[51.445806, "o", "\r\n\u001b[36mfastapi_app |\u001b[0m \r\n\u001b[36mfastapi_app |\u001b[0m During handling of the above exception, another exception occurred:\r\n\u001b[36mfastapi_app |\u001b[0m \r\n\u001b[36mfastapi_app |\u001b[0m Traceback (most recent call last):\r\n\u001b[36mfastapi_app |\u001b[0m   File \"/usr/local/lib/python3.11/site-packages/sqlalchemy/engine/base.py\", line 145, in __init__\r\n\u001b[36mfastapi_app |\u001b[0m     self._dbapi_connection = engine.raw_connection()\r\n\u001b[36mfastapi_app |\u001b[0m                              ^^^^^^^^^^^^^^^^^^^^^^^\r\n\u001b[36mfastapi_app |\u001b[0m   File \"/usr/local/lib/python3.11/site-packages/sqlalchemy/engine/base.py\", line 3297, in raw_connection\r\n\u001b[36mfastapi_app |\u001b[0m     return self.pool.connect()\r\n\u001b[36mfastapi_app |\u001b[0m            ^^^^^^^^^^^^^^^^^^^\r\n\u001b[36mfastapi_app |\u001b[0m   File \"/usr/local/lib/python3.11/site-packages/sqlalchemy/pool/base.py\", line 449, in connect\r\n\u001b[36mfastapi_app |\u001b[0m     return _ConnectionFairy._checkout(self)\r\n\u001b[36mfastapi_app |\u001b[0m            ^^^^^^^^^^^^^^^^^^^^^^^^^^^^^^^^\r\n\u001b[36mfastapi_app |\u001b[0m   File \"/usr/local/lib/pytho"]
[51.445859, "o", "n3.11/site-packages/sqlalchemy/pool/base.py\", line 1264, in _checkout\r\n\u001b[36mfastapi_app |\u001b[0m     fairy = _ConnectionRecord.checkout(pool)\r\n\u001b[36mfastapi_app |\u001b[0m             ^^^^^^^^^^^^^^^^^^^^^^^^^^^^^^^^\r\n\u001b[36mfastapi_app |\u001b[0m   File \"/usr/local/lib/python3.11/site-packages/sqlalchemy/pool/base.py\", line 713, in checkout\r\n\u001b[36mfastapi_app |\u001b[0m     rec = pool._do_get()\r\n\u001b[36mfastapi_app |\u001b[0m           ^^^^^^^^^^^^^^\r\n\u001b[36mfastapi_app |\u001b[0m   File \"/usr/local/lib/python3.11/site-packages/sqlalchemy/pool/impl.py\", line 179, in _do_get\r\n\u001b[36mfastapi_app |\u001b[0m     with util.safe_reraise():\r\n\u001b[36mfastapi_app |\u001b[0m   File \"/usr/local/lib/python3.11/site-packages/sqlalchemy/util/langhelpers.py\", line 224, in __exit__\r\n\u001b[36mfastapi_app |\u001b[0m     raise exc_value.with_traceback(exc_tb)\r\n\u001b[36mfastapi_app |\u001b[0m   File \"/usr/local/lib/python3.11/site-packages/sqlalchemy/pool/impl.py\", line 177, in _do_get\r\n\u001b[36mfastapi_app |\u001b[0m     return self._create_connection()\r\n\u001b[36mfastapi_app |\u001b[0m            ^^^^^^^^^^^^^^^^"]
[51.445874, "o", "^^^^^^^^^\r\n\u001b[36mfastapi_app |\u001b[0m   File \"/usr/local/lib/python3.11/site-packages/sqlalchemy/pool/base.py\", line 390, in _create_connection\r\n\u001b[36mfastapi_app |\u001b[0m     return _ConnectionRecord(self)\r\n\u001b[36mfastapi_app |\u001b[0m            ^^^^^^^^^^^^^^^^^^^^^^^\r\n\u001b[36mfastapi_app |\u001b[0m   File \"/usr/local/lib/python3.11/site-packages/sqlalchemy/pool/base.py\", line 675, in __init__\r\n\u001b[36mfastapi_app |\u001b[0m     self.__connect()\r\n\u001b[36mfastapi_app |\u001b[0m   File \"/usr/local/lib/python3.11/site-packages/sqlalchemy/pool/base.py\", line 901, in __connect\r\n\u001b[36mfastapi_app |\u001b[0m     with util.safe_reraise():\r\n\u001b[36mfastapi_app |\u001b[0m   File \"/usr/local/lib/python3.11/site-packages/sqlalchemy/util/langhelpers.py\", line 224, in __exit__\r\n\u001b[36mfastapi_app |\u001b[0m     raise exc_value.with_traceback(exc_tb)\r\n\u001b[36mfastapi_app |\u001b[0m   File \"/usr/local/lib/python3.11/site-packages/sqlalchemy/pool/base.py\", line 897, in __connect\r\n\u001b[36mfastapi_app |\u001b[0m     self.dbapi_connection = connection = pool._invoke_creator(self)\r\n\u001b[36mfastapi_app |"]
[51.445894, "o", "\u001b[0m                                          ^^^^^^^^^^^^^^^^^^^^^^^^^^\r\n\u001b[36mfastapi_app |\u001b[0m   File \"/usr/local/lib/python3.11/site-packages/sqlalchemy/engine/create.py\", line 646, in connect\r\n\u001b[36mfastapi_app |\u001b[0m     return dialect.connect(*cargs, **cparams)\r\n\u001b[36mfastapi_app |\u001b[0m            ^^^^^^^^^^^^^^^^^^^^^^^^^^^^^^^^^^\r\n\u001b[36mfastapi_app |\u001b[0m   File \"/usr/local/lib/python3.11/site-packages/sqlalchemy/engine/default.py\", line 625, in connect\r\n\u001b[36mfastapi_app |\u001b[0m     return self.loaded_dbapi.connect(*cargs, **cparams)  # type: ignore[no-any-return]  # NOQA: E501\r\n\u001b[36mfastapi_app |\u001b[0m            ^^^^^^^^^^^^^^^^^^^^^^^^^^^^^^^^^^^^^^^^^^^^\r\n\u001b[36mfastapi_app |\u001b[0m   File \"/usr/local/lib/python3.11/site-packages/pymysql/connections.py\", line 361, in __init__\r\n\u001b[36mfastapi_app |\u001b[0m     self.connect()\r\n\u001b[36mfastapi_app |\u001b[0m   File \"/usr/local/lib/python3.11/site-packages/pymysql/connections.py\", line 716, in connect\r\n\u001b[36mfastapi_app |\u001b[0m     raise exc\r\n\u001b[36mfastapi_app |\u001b[0m pymysql.err.Oper"]
[51.446372, "o", "ationalError: (2003, \"Can't connect to MySQL server on 'db' ([Errno 111] Connection refused)\")\r\n\u001b[36mfastapi_app |\u001b[0m \r\n\u001b[36mfastapi_app |\u001b[0m The above exception was the direct cause of the following exception:\r\n\u001b[36mfastapi_app |\u001b[0m \r\n\u001b[36mfastapi_app |\u001b[0m Traceback (most recent call last):\r\n\u001b[36mfastapi_app |\u001b[0m   File \"/usr/local/lib/python3.11/site-packages/starlette/routing.py\", line 692, in lifespan\r\n\u001b[36mfastapi_app |\u001b[0m     async with self.lifespan_context(app) as maybe_state:\r\n\u001b[36mfastapi_app |\u001b[0m   File \"/usr/local/lib/python3.11/site-packages/starlette/routing.py\", line 569, in __aenter__\r\n\u001b[36mfastapi_app |\u001b[0m     await self._router.startup()\r\n\u001b[36mfastapi_app |\u001b[0m   File \"/usr/local/lib/python3.11/site-packages/starlette/routing.py\", line 671, in startup\r\n\u001b[36mfastapi_app |\u001b[0m     handler()\r\n\u001b[36mfastapi_app |\u001b[0m   File \"/app/main.py\", line 172, in startup_event\r\n\u001b[36mfastapi_app |\u001b[0m     create_tables()\r\n\u001b[36mfastapi_app |\u001b[0m   File \"/app/main.py\", line 119, in create_tables\r\n\u001b[36m"]
[51.446442, "o", "fastapi_app |\u001b[0m     Base.metadata.create_all(bind=engine)\r\n\u001b[36mfastapi_app |\u001b[0m   File \"/usr/local/lib/python3.11/site-packages/sqlalchemy/sql/schema.py\", line 5924, in create_all\r\n\u001b[36mfastapi_app |\u001b[0m     bind._run_ddl_visitor(\r\n\u001b[36mfastapi_app |\u001b[0m   File \"/usr/local/lib/python3.11/site-packages/sqlalchemy/engine/base.py\", line 3247, in _run_ddl_visitor\r\n\u001b[36mfastapi_app |\u001b[0m     with self.begin() as conn:\r\n\u001b[36mfastapi_app |\u001b[0m   File \"/usr/local/lib/python3.11/contextlib.py\", line 137, in __enter__\r\n\u001b[36mfastapi_app |\u001b[0m     return next(self.gen)\r\n\u001b[36mfastapi_app |\u001b[0m            ^^^^^^^^^^^^^^\r\n\u001b[36mfastapi_app |\u001b[0m   File \"/usr/local/lib/python3.11/site-packages/sqlalchemy/engine/base.py\", line 3237, in begin\r\n\u001b[36mfastapi_app |\u001b[0m     with self.connect() as conn:\r\n\u001b[36mfastapi_app |\u001b[0m          ^^^^^^^^^^^^^^\r\n\u001b[36mfastapi_app |\u001b[0m   File \"/usr/local/lib/python3.11/site-packages/sqlalchemy/engine/base.py\", line 3273, in connect\r\n\u001b[36mfastapi_app |\u001b[0m     return self._connection_cls(sel"]
[51.446478, "o", "f)\r\n\u001b[36mfastapi_app |\u001b[0m            ^^^^^^^^^^^^^^^^^^^^^^^^^^\r\n\u001b[36mfastapi_app |\u001b[0m   File \"/usr/local/lib/python3.11/site-packages/sqlalchemy/engine/base.py\", line 147, in __init__\r\n\u001b[36mfastapi_app |\u001b[0m     Connection._handle_dbapi_exception_noconnection(\r\n\u001b[36mfastapi_app |\u001b[0m   File \"/usr/local/lib/python3.11/site-packages/sqlalchemy/engine/base.py\", line 2436, in _handle_dbapi_exception_noconnection\r\n\u001b[36mfastapi_app |\u001b[0m     raise sqlalchemy_exception.with_traceback(exc_info[2]) from e\r\n\u001b[36mfastapi_app |\u001b[0m   File \"/usr/local/lib/python3.11/site-packages/sqlalchemy/engine/base.py\", line 145, in __init__\r\n\u001b[36mfastapi_app |\u001b[0m     self._dbapi_connection = engine.raw_connection()\r\n\u001b[36mfastapi_app |\u001b[0m                              ^^^^^^^^^^^^^^^^^^^^^^^\r\n\u001b[36mfastapi_app |\u001b[0m   File \"/usr/local/lib/python3.11/site-packages/sqlalchemy/engine/base.py\", line 3297, in raw_connection\r\n\u001b[36mfastapi_app |\u001b[0m     return self.pool.connect()\r\n\u001b[36mfastapi_app |\u001b[0m            ^^^^^^^^^^^^^^^^^^^\r\n\u001b[3"]
[51.446514, "o", "6mfastapi_app |\u001b[0m   File \"/usr/local/lib/python3.11/site-packages/sqlalchemy/pool/base.py\", line 449, in connect\r\n\u001b[36mfastapi_app |\u001b[0m     return _ConnectionFairy._checkout(self)\r\n\u001b[36mfastapi_app |\u001b[0m            ^^^^^^^^^^^^^^^^^^^^^^^^^^^^^^^^\r\n\u001b[36mfastapi_app |\u001b[0m   File \"/usr/local/lib/python3.11/site-packages/sqlalchemy/pool/base.py\", line 1264, in _checkout\r\n\u001b[36mfastapi_app |\u001b[0m     fairy = _ConnectionRecord.checkout(pool)\r\n\u001b[36mfastapi_app |\u001b[0m             ^^^^^^^^^^^^^^^^^^^^^^^^^^^^^^^^\r\n\u001b[36mfastapi_app |\u001b[0m   File \"/usr/local/lib/python3.11/site-packages/sqlalchemy/pool/base.py\", line 713, in checkout\r\n\u001b[36mfastapi_app |\u001b[0m     rec = pool._do_get()\r\n\u001b[36mfastapi_app |\u001b[0m           ^^^^^^^^^^^^^^\r\n\u001b[36mfastapi_app |\u001b[0m   File \"/usr/local/lib/python3.11/site-packages/sqlalchemy/pool/impl.py\", line 179, in _do_get\r\n\u001b[36mfastapi_app |\u001b[0m     with util.safe_reraise():\r\n\u001b[36mfastapi_app |\u001b[0m   File \"/usr/local/lib/python3.11/site-packages/sqlalchemy/util/langhelpers.py\", line 224, in __ex"]
[51.446799, "o", "it__\r\n\u001b[36mfastapi_app |\u001b[0m     raise exc_value.with_traceback(exc_tb)\r\n\u001b[36mfastapi_app |\u001b[0m   File \"/usr/local/lib/python3.11/site-packages/sqlalchemy/pool/impl.py\", line 177, in _do_get\r\n\u001b[36mfastapi_app |\u001b[0m     return self._create_connection()\r\n\u001b[36mfastapi_app |\u001b[0m            ^^^^^^^^^^^^^^^^^^^^^^^^^\r\n\u001b[36mfastapi_app |\u001b[0m   File \"/usr/local/lib/python3.11/site-packages/sqlalchemy/pool/base.py\", line 390, in _create_connection\r\n\u001b[36mfastapi_app |\u001b[0m     return _ConnectionRecord(self)\r\n\u001b[36mfastapi_app |\u001b[0m            ^^^^^^^^^^^^^^^^^^^^^^^\r\n\u001b[36mfastapi_app |\u001b[0m   File \"/usr/local/lib/python3.11/site-packages/sqlalchemy/pool/base.py\", line 675, in __init__\r\n\u001b[36mfastapi_app |\u001b[0m     self.__connect()\r\n\u001b[36mfastapi_app |\u001b[0m   File \"/usr/local/lib/python3.11/site-packages/sqlalchemy/pool/base.py\", line 901, in __connect\r\n\u001b[36mfastapi_app |\u001b[0m     with util.safe_reraise():\r\n\u001b[36mfastapi_app |\u001b[0m   File \"/usr/local/lib/python3.11/site-packages/sqlalchemy/util/langhelpers.py\", line 224, in __exi"]
[51.446898, "o", "t__\r\n\u001b[36mfastapi_app |\u001b[0m     raise exc_value.with_traceback(exc_tb)\r\n\u001b[36mfastapi_app |\u001b[0m   File \"/usr/local/lib/python3.11/site-packages/sqlalchemy/pool/base.py\", line 897, in __connect\r\n\u001b[36mfastapi_app |\u001b[0m     self.dbapi_connection = connection = pool._invoke_creator(self)\r\n\u001b[36mfastapi_app |\u001b[0m                                          ^^^^^^^^^^^^^^^^^^^^^^^^^^\r\n\u001b[36mfastapi_app |\u001b[0m   File \"/usr/local/lib/python3.11/site-packages/sqlalchemy/engine/create.py\", line 646, in connect\r\n\u001b[36mfastapi_app |\u001b[0m     return dialect.connect(*cargs, **cparams)\r\n\u001b[36mfastapi_app |\u001b[0m            ^^^^^^^^^^^^^^^^^^^^^^^^^^^^^^^^^^\r\n\u001b[36mfastapi_app |\u001b[0m   File \"/usr/local/lib/python3.11/site-packages/sqlalchemy/engine/default.py\", line 625, in connect\r\n\u001b[36mfastapi_app |\u001b[0m     return self.loaded_dbapi.connect(*cargs, **cparams)  # type: ignore[no-any-return]  # NOQA: E501\r\n\u001b[36mfastapi_app |\u001b[0m            ^^^^^^^^^^^^^^^^^^^^^^^^^^^^^^^^^^^^^^^^^^^^\r\n\u001b[36mfastapi_app |\u001b[0m   File \"/usr/local/lib/python3.1"]
[51.446918, "o", "1/site-packages/pymysql/connections.py\", line 361, in __init__\r\n\u001b[36mfastapi_app |\u001b[0m     self.connect()\r\n\u001b[36mfastapi_app |\u001b[0m   File \"/usr/local/lib/python3.11/site-packages/pymysql/connections.py\", line 716, in connect\r\n\u001b[36mfastapi_app |\u001b[0m     raise exc\r\n\u001b[36mfastapi_app |\u001b[0m sqlalchemy.exc.OperationalError: (pymysql.err.OperationalError) (2003, \"Can't connect to MySQL server on 'db' ([Errno 111] Connection refused)\")\r\n\u001b[36mfastapi_app |\u001b[0m (Background on this error at: https://sqlalche.me/e/20/e3q8)\r\n\u001b[36mfastapi_app |\u001b[0m \r\n\u001b[36mfastapi_app |\u001b[0m ERROR:    Application startup failed. Exiting.\r\n"]
[52.43901, "o", "\u001b[33mmysql_db |\u001b[0m 2025-06-15T21:43:23.488098Z 1 [System] [MY-013577] [InnoDB] InnoDB initialization has ended."]
[52.440235, "o", "\r\n"]
[54.051039, "o", "\u001b[33mmysql_db |\u001b[0m 2025-06-15T21:43:25.085505Z 0 [Warning] [MY-010068] [Server] CA certificate ca.pem is self signed.\r\n\u001b[33mmysql_db |\u001b[0m 2025-06-15T21:43:25.088658Z 0 [System] [MY-013602] [Server] Channel mysql_main configured to support TLS. Encrypted connections are now supported for this channel.\r\n"]
[54.080303, "o", "\u001b[33mmysql_db |\u001b[0m 2025-06-15T21:43:25.120267Z 0 [Warning] [MY-011810] [Server] Insecure configuration for --pid-file: Location '/var/run/mysqld' in the path is accessible to all OS users. Consider choosing a different directory.\r\n"]
[54.250325, "o", "\u001b[33mmysql_db |\u001b[0m 2025-06-15T21:43:25.299518Z 0 [System] [MY-010931] [Server] /usr/sbin/mysqld: ready for connections. Version: '8.4.5'  socket: '/var/run/mysqld/mysqld.sock'  port: 3306  MySQL Community Server - GPL."]
[54.250769, "o", "\r\n"]
[54.251244, "o", "\u001b[33mmysql_db |\u001b[0m 2025-06-15T21:43:25.300482Z 0 [System] [MY-011323] [Server] X Plugin ready for connections. Bind-address: '::' port: 33060, socket: /var/run/mysqld/mysqlx.sock\r\n"]
[56.95405, "o", "\u001b[32mfastapi_app |\u001b[0m INFO:     Started server process [1]\r\n\u001b[32mfastapi_app |\u001b[0m INFO:     Waiting for application startup.\r\n"]
[57.019509, "o", "\u001b[32mfastapi_app |\u001b[0m INFO:     Application startup complete.\r\n\u001b[32mfastapi_app |\u001b[0m INFO:     Uvicorn running on http://0.0.0.0:8000 (Press CTRL+C to quit)\r\n"]
[66.198206, "o", "\u001b[32mfastapi_app |\u001b[0m INFO:     172.18.0.1:55092 - \"POST /users/ HTTP/1.1\" 400 Bad Request\r\n"]
[80.494064, "o", "\u001b[32mfastapi_app |\u001b[0m INFO:     172.18.0.1:44282 - \"POST /token HTTP/1.1\" 200 OK\r\n"]
[181.236844, "o", "\u001b[32mfastapi_app |\u001b[0m INFO:     172.18.0.1:56868 - \"POST /tasks/ HTTP/1.1\" 200 OK\r\n"]
[189.140295, "o", "\u001b[32mfastapi_app |\u001b[0m INFO:     172.18.0.1:41508 - \"GET /tasks/ HTTP/1.1\" 200 OK\r\n"]
[238.277456, "o", "\u001b[32mfastapi_app |\u001b[0m INFO:     172.18.0.1:37554 - \"PUT /tasks/4 HTTP/1.1\" 200 OK\r\n"]
[301.28219, "o", "\u001b[32mfastapi_app |\u001b[0m INFO:     172.18.0.1:34286 - \"DELETE /tasks/4 HTTP/1.1\" 200 OK\r\n"]
[317.146923, "o", "\u001b[32mfastapi_app |\u001b[0m INFO:     172.18.0.1:40498 - \"POST /tasks/ HTTP/1.1\" 401 Unauthorized\r\n"]
[332.100715, "o", "\u001b[32mfastapi_app |\u001b[0m INFO:     172.18.0.1:45100 - \"POST /tasks/ HTTP/1.1\" 200 OK\r\n"]
[342.767935, "o", "\u001b[32mfastapi_app |\u001b[0m INFO:     Shutting down\r\n"]
[342.862358, "o", "\u001b[32mfastapi_app |\u001b[0m INFO:     Waiting for application shutdown.\r\n"]
[342.86272, "o", "\u001b[32mfastapi_app |\u001b[0m INFO:     Application shutdown complete.\r\n\u001b[32mfastapi_app |\u001b[0m INFO:     Finished server process [1]\r\n"]
[343.559, "o", "\u001b[36mfastapi_app exited with code 0\r\n\u001b[0m"]
[343.573551, "o", "\u001b[32mfastapi_app exited with code 0\r\n\u001b[0m"]
[343.63045, "o", "\u001b[33mmysql_db |\u001b[0m 2025-06-15T21:48:14.651289Z 0 [System] [MY-013172] [Server] Received SHUTDOWN from user <via user signal>. Shutting down mysqld (Version: 8.4.5).\r\n"]
[344.647236, "o", "\u001b[33mmysql_db |\u001b[0m 2025-06-15T21:48:15.696770Z 0 [System] [MY-010910] [Server] /usr/sbin/mysqld: Shutdown complete (mysqld 8.4.5)  MySQL Community Server - GPL.\r\n\u001b[33mmysql_db |\u001b[0m 2025-06-15T21:48:15.696800Z 0 [System] [MY-015016] [Server] MySQL Server - end.\r\n"]
[345.062336, "o", "\u001b[33mmysql_db exited with code 0\r\n\u001b[0m"]
[345.549188, "o", "\u001b[?2004h"]
[345.550156, "o", "\u001b]0;alena@alena-VirtualBox: ~/fast_api2\u0007\u001b[01;32malena@alena-VirtualBox\u001b[00m:\u001b[01;34m~/fast_api2\u001b[00m$ "]
[431.402872, "o", "e"]
[431.63812, "o", "x"]
[431.770129, "o", "i"]
[431.952325, "o", "t"]
[432.170762, "o", "\r\n\u001b[?2004l\rexit\r\n"]
